Workbook

Sheet PolicyActions
A1: id | B1: action | C1: type
A2: 1 | B2: Expansionary fiscal policy | C2: fiscal_policy
A3: 2 | B3: Increase government spending | C3: fiscal_policy
A4: 3 | B4: Increase transfer payments (e.g. unemployment benefits) | C4: fiscal_policy
A5: 4 | B5: Decrease taxes | C5: fiscal_policy
A6: 5 | B6: Contractionary fiscal policy | C6: fiscal_policy
A7: 6 | B7: Decrease government spending | C7: fiscal_policy
A8: 7 | B8: Decrease transfer payments | C8: fiscal_policy
A9: 8 | B9: Increase taxes | C9: fiscal_policy
A10: 9 | B10: Expansionary monetary policy | C10: monetary_policy
A11: 10 | B11: Decrease required reserve ratio | C11: monetary_policy
A12: 11 | B12: Decrease reserve requirement | C12: monetary_policy
A13: 12 | B13: Buy government bonds / securities | C13: monetary_policy
... A27: 26 | B27: Increase administered interest rates | C27: monetary_policy

Sheet EconomicVariables
A1: id | B1: name | C1: category
A2: 1 | B2: Aggregate Demand | C2: macro_indicator
A3: 2 | B3: Price Level | C3: macro_indicator
A4: 3 | B4: Real GDP | C4: macro_indicator
A5: 4 | B5: Unemployment Rate | C5: macro_indicator
A6: 5 | B6: Money Supply | C6: financial_indicator
A7: 6 | B7: Interest Rate | C7: financial_indicator
A8: 7 | B8: Bond Price | C8: financial_indicator
A9: 8 | B9: Interest-sensitive Private Spending (Investment & Consumption) | C9: expenditure
A10: 9 | B10: Economic Growth (LRAS, PPC) | C10: macro_indicator

Sheet PolicyEffects
A1: policyId | C1: variableId | E1: effect | F1: explanation
A2: 1 | B2: =VLOOKUP(A2,PolicyActions!A:B,2,FALSE) -> Expansionary fiscal policy | C2: 1 | D2: =VLOOKUP(C2,EconomicVariables!A:B,2,FALSE) -> Aggregate Demand | E2: increase | F2: Expansionary fiscal policy刺激经济，增加AD。政府支出直接影响AD，税和转移支付影响disposable income，间接影响private spending和AD。（但如有deficit，政府借债可能会crowd out部分private spending）
A3: 1 | B3: =VLOOKUP(A3,PolicyActions!A:B,2,FALSE) -> Expansionary fiscal policy | C3: 2 | D3: =VLOOKUP(C3,EconomicVariables!A:B,2,FALSE) -> Price Level | E3: increase | F3: Expansionary fiscal policy刺激经济，增加AD，见AD-AS diagram
A4: 1 | B4: =VLOOKUP(A4,PolicyActions!A:B,2,FALSE) -> Expansionary fiscal policy | C4: 3 | D4: =VLOOKUP(C4,EconomicVariables!A:B,2,FALSE) -> Real GDP | E4: increase | F4: Expansionary fiscal policy刺激经济，增加AD，见AD-AS diagram
A5: 1 | B5: =VLOOKUP(A5,PolicyActions!A:B,2,FALSE) -> Expansionary fiscal policy | C5: 4 | D5: =VLOOKUP(C5,EconomicVariables!A:B,2,FALSE) -> Unemployment Rate | E5: decrease | F5: 失业率通常与real GDP反向。（Expansionary fiscal policy刺激经济，增加AD，见AD-AS diagram）
A6: 1 | B6: =VLOOKUP(A6,PolicyActions!A:B,2,FALSE) -> Expansionary fiscal policy | C6: 6 | D6: =VLOOKUP(C6,EconomicVariables!A:B,2,FALSE) -> Interest Rate | E6: increase | F6: Expansionary fiscal policy使public savings=tax-(government spending+transfers)降低，减少Supply of Loans（或增加deficit spending进而增加Demand for Loans)，因而利率上升。见loanable funds market diagram
A7: 1 | B7: =VLOOKUP(A7,PolicyActions!A:B,2,FALSE) -> Expansionary fiscal policy | C7: 7 | D7: =VLOOKUP(C7,EconomicVariables!A:B,2,FALSE) -> Bond Price | E7: decrease | F7: 债券价格与利率反向。（Expansionary fiscal policy使public savings=tax-(government spending+transfers)降低，减少Supply of Loans（或增加deficit spending进而增加Demand for Loans)，因而利率上升。见loanable funds market diagram）
A8: 1 | B8: =VLOOKUP(A8,PolicyActions!A:B,2,FALSE) -> Expansionary fiscal policy | C8: 8 | D8: =VLOOKUP(C8,EconomicVariables!A:B,2,FALSE) -> Interest-sensitive Private Spending (Investment & Consumption) | E8: decrease | F8: Interest-sensitive Private Spending (Investment & Consumption)与利率反向。（Expansionary fiscal policy使public savings=tax-(government spending+transfers)降低，减少Supply of Loans（或增加deficit spending进而增加Demand for Loans)，因而利率上升。见loanable funds market diagram）
A9: 1 | B9: =VLOOKUP(A9,PolicyActions!A:B,2,FALSE) -> Expansionary fiscal policy | C9: 9 | D9: =VLOOKUP(C9,EconomicVariables!A:B,2,FALSE) -> Economic Growth (LRAS, PPC) | E9: decrease | F9: Investment与利率反向，长期会影响capital stock资本存量（属于资源数量）和潜在产能。（Expansionary fiscal policy使public savings=tax-(government spending+transfers)降低，减少Supply of Loans（或增加deficit spending进而增加Demand for Loans)，因而利率上升。见loanable funds market diagram）
A10: 2 | B10: =VLOOKUP(A10,PolicyActions!A:B,2,FALSE) -> Increase government spending | C10: 1 | D10: =VLOOKUP(C10,EconomicVariables!A:B,2,FALSE) -> Aggregate Demand | E10: increase | F10: =F2 -> Expansionary fiscal policy刺激经济，增加AD。政府支出直接影响AD，税和转移支付影响disposable income，间接影响private spending和AD。（但如有deficit，政府借债可能会crowd out部分private spending）
A11: 2 | B11: =VLOOKUP(A11,PolicyActions!A:B,2,FALSE) -> Increase government spending | C11: 2 | D11: =VLOOKUP(C11,EconomicVariables!A:B,2,FALSE) -> Price Level | E11: increase | F11: =F3 -> Expansionary fiscal policy刺激经济，增加AD，见AD-AS diagram
A12: 2 | B12: =VLOOKUP(A12,PolicyActions!A:B,2,FALSE) -> Increase government spending | C12: 3 | D12: =VLOOKUP(C12,EconomicVariables!A:B,2,FALSE) -> Real GDP | E12: increase | F12: =F4 -> Expansionary fiscal policy刺激经济，增加AD，见AD-AS diagram
A13: 2 | B13: =VLOOKUP(A13,PolicyActions!A:B,2,FALSE) -> Increase government spending | C13: 4 | D13: =VLOOKUP(C13,EconomicVariables!A:B,2,FALSE) -> Unemployment Rate | E13: decrease | F13: =F5 -> 失业率通常与real GDP反向。（Expansionary fiscal policy刺激经济，增加AD，见AD-AS diagram）
A14: 2 | B14: =VLOOKUP(A14,PolicyActions!A:B,2,FALSE) -> Increase government spending | C14: 6 | D14: =VLOOKUP(C14,EconomicVariables!A:B,2,FALSE) -> Interest Rate | E14: increase | F14: =F6 -> Expansionary fiscal policy使public savings=tax-(government spending+transfers)降低，减少Supply of Loans（或增加deficit spending进而增加Demand for Loans)，因而利率上升。见loanable funds market diagram
A15: 2 | B15: =VLOOKUP(A15,PolicyActions!A:B,2,FALSE) -> Increase government spending | C15: 7 | D15: =VLOOKUP(C15,EconomicVariables!A:B,2,FALSE) -> Bond Price | E15: decrease | F15: =F7 -> 债券价格与利率反向。（Expansionary fiscal policy使public savings=tax-(government spending+transfers)降低，减少Supply of Loans（或增加deficit spending进而增加Demand for Loans)，因而利率上升。见loanable funds market diagram）
A16: 2 | B16: =VLOOKUP(A16,PolicyActions!A:B,2,FALSE) -> Increase government spending | C16: 8 | D16: =VLOOKUP(C16,EconomicVariables!A:B,2,FALSE) -> Interest-sensitive Private Spending (Investment & Consumption) | E16: decrease | F16: =F8 -> Interest-sensitive Private Spending (Investment & Consumption)与利率反向。（Expansionary fiscal policy使public savings=tax-(government spending+transfers)降低，减少Supply of Loans（或增加deficit spending进而增加Demand for Loans)，因而利率上升。见loanable funds market diagram）
A17: 2 | B17: =VLOOKUP(A17,PolicyActions!A:B,2,FALSE) -> Increase government spending | C17: 9 | D17: =VLOOKUP(C17,EconomicVariables!A:B,2,FALSE) -> Economic Growth (LRAS, PPC) | E17: decrease | F17: =F9 -> Investment与利率反向，长期会影响capital stock资本存量（属于资源数量）和潜在产能。（Expansionary fiscal policy使public savings=tax-(government spending+transfers)降低，减少Supply of Loans（或增加deficit spending进而增加Demand for Loans)，因而利率上升。见loanable funds market diagram）
A18: 3 | B18: =VLOOKUP(A18,PolicyActions!A:B,2,FALSE) -> Increase transfer payments (e.g. unemployment benefits) | C18: 1 | D18: =VLOOKUP(C18,EconomicVariables!A:B,2,FALSE) -> Aggregate Demand | E18: increase | F18: =F10 -> Expansionary fiscal policy刺激经济，增加AD。政府支出直接影响AD，税和转移支付影响disposable income，间接影响private spending和AD。（但如有deficit，政府借债可能会crowd out部分private spending）
A19: 3 | B19: =VLOOKUP(A19,PolicyActions!A:B,2,FALSE) -> Increase transfer payments (e.g. unemployment benefits) | C19: 2 | D19: =VLOOKUP(C19,EconomicVariables!A:B,2,FALSE) -> Price Level | E19: increase | F19: =F11 -> Expansionary fiscal policy刺激经济，增加AD，见AD-AS diagram
A20: 3 | B20: =VLOOKUP(A20,PolicyActions!A:B,2,FALSE) -> Increase transfer payments (e.g. unemployment benefits) | C20: 3 | D20: =VLOOKUP(C20,EconomicVariables!A:B,2,FALSE) -> Real GDP | E20: increase | F20: =F12 -> Expansionary fiscal policy刺激经济，增加AD，见AD-AS diagram
A21: 3 | B21: =VLOOKUP(A21,PolicyActions!A:B,2,FALSE) -> Increase transfer payments (e.g. unemployment benefits) | C21: 4 | D21: =VLOOKUP(C21,EconomicVariables!A:B,2,FALSE) -> Unemployment Rate | E21: decrease | F21: =F13 -> 失业率通常与real GDP反向。（Expansionary fiscal policy刺激经济，增加AD，见AD-AS diagram）
... A33: 4 | B33: =VLOOKUP(A33,PolicyActions!A:B,2,FALSE) -> Decrease taxes | C33: 9 | D33: =VLOOKUP(C33,EconomicVariables!A:B,2,FALSE) -> Economic Growth (LRAS, PPC) | E33: decrease | F33: =F25 -> Investment与利率反向，长期会影响capital stock资本存量（属于资源数量）和潜在产能。（Expansionary fiscal policy使public savings=tax-(government spending+transfers)降低，减少Supply of Loans（或增加deficit spending进而增加Demand for Loans)，因而利率上升。见loanable funds market diagram）
A34: 5 | B34: =VLOOKUP(A34,PolicyActions!A:B,2,FALSE) -> Contractionary fiscal policy | C34: 1 | D34: =VLOOKUP(C34,EconomicVariables!A:B,2,FALSE) -> Aggregate Demand | E34: decrease | F34: Contractionary fiscal policy减少AD，政府支出直接影响AD，税和转移支付影响disposable income，间接影响private spending和AD。
A35: 5 | B35: =VLOOKUP(A35,PolicyActions!A:B,2,FALSE) -> Contractionary fiscal policy | C35: 2 | D35: =VLOOKUP(C35,EconomicVariables!A:B,2,FALSE) -> Price Level | E35: decrease | F35: Contractionary fiscal policy减少AD，见AD-AS diagram
A36: 5 | B36: =VLOOKUP(A36,PolicyActions!A:B,2,FALSE) -> Contractionary fiscal policy | C36: 3 | D36: =VLOOKUP(C36,EconomicVariables!A:B,2,FALSE) -> Real GDP | E36: decrease | F36: Contractionary fiscal policy减少AD，见AD-AS diagram
A37: 5 | B37: =VLOOKUP(A37,PolicyActions!A:B,2,FALSE) -> Contractionary fiscal policy | C37: 4 | D37: =VLOOKUP(C37,EconomicVariables!A:B,2,FALSE) -> Unemployment Rate | E37: increase | F37: 失业率通常与real GDP反向。（Contractionary fiscal policy减少AD，见AD-AS diagram）
A38: 5 | B38: =VLOOKUP(A38,PolicyActions!A:B,2,FALSE) -> Contractionary fiscal policy | C38: 6 | D38: =VLOOKUP(C38,EconomicVariables!A:B,2,FALSE) -> Interest Rate | E38: decrease | F38: Contractionary fiscal policy使public savings=tax-(government spending+transfers)增加，增加Supply of Loans（或减少deficit spending进而减少Demand for Loans)，因而利率下降。见loanable funds market diagram
A39: 5 | B39: =VLOOKUP(A39,PolicyActions!A:B,2,FALSE) -> Contractionary fiscal policy | C39: 7 | D39: =VLOOKUP(C39,EconomicVariables!A:B,2,FALSE) -> Bond Price | E39: increase | F39: 债券价格与利率反向。（Contractionary fiscal policy使public savings=tax-(government spending+transfers)增加，增加Supply of Loans（或减少deficit spending进而减少Demand for Loans)，因而利率下降。见loanable funds market diagram）
A40: 5 | B40: =VLOOKUP(A40,PolicyActions!A:B,2,FALSE) -> Contractionary fiscal policy | C40: 8 | D40: =VLOOKUP(C40,EconomicVariables!A:B,2,FALSE) -> Interest-sensitive Private Spending (Investment & Consumption) | E40: increase | F40: Interest-sensitive Private Spending (Investment & Consumption)与利率反向。（Contractionary fiscal policy使public savings=tax-(government spending+transfers)增加，增加Supply of Loans（或减少deficit spending进而减少Demand for Loans)，因而利率下降。见loanable funds market diagram）
A41: 5 | B41: =VLOOKUP(A41,PolicyActions!A:B,2,FALSE) -> Contractionary fiscal policy | C41: 9 | D41: =VLOOKUP(C41,EconomicVariables!A:B,2,FALSE) -> Economic Growth (LRAS, PPC) | E41: increase | F41: Investment与利率反向，长期会影响capital stock资本存量（属于资源数量）和潜在产能。（Contractionary fiscal policy使public savings=tax-(government spending+transfers)增加，增加Supply of Loans（或减少deficit spending进而减少Demand for Loans)，因而利率下降。见loanable funds market diagram）
A42: 6 | B42: =VLOOKUP(A42,PolicyActions!A:B,2,FALSE) -> Decrease government spending | C42: 1 | D42: =VLOOKUP(C42,EconomicVariables!A:B,2,FALSE) -> Aggregate Demand | E42: decrease | F42: =F34 -> Contractionary fiscal policy减少AD，政府支出直接影响AD，税和转移支付影响disposable income，间接影响private spending和AD。
A43: 6 | B43: =VLOOKUP(A43,PolicyActions!A:B,2,FALSE) -> Decrease government spending | C43: 2 | D43: =VLOOKUP(C43,EconomicVariables!A:B,2,FALSE) -> Price Level | E43: decrease | F43: =F35 -> Contractionary fiscal policy减少AD，见AD-AS diagram
A44: 6 | B44: =VLOOKUP(A44,PolicyActions!A:B,2,FALSE) -> Decrease government spending | C44: 3 | D44: =VLOOKUP(C44,EconomicVariables!A:B,2,FALSE) -> Real GDP | E44: decrease | F44: =F36 -> Contractionary fiscal policy减少AD，见AD-AS diagram
A45: 6 | B45: =VLOOKUP(A45,PolicyActions!A:B,2,FALSE) -> Decrease government spending | C45: 4 | D45: =VLOOKUP(C45,EconomicVariables!A:B,2,FALSE) -> Unemployment Rate | E45: increase | F45: =F37 -> 失业率通常与real GDP反向。（Contractionary fiscal policy减少AD，见AD-AS diagram）
A46: 6 | B46: =VLOOKUP(A46,PolicyActions!A:B,2,FALSE) -> Decrease government spending | C46: 6 | D46: =VLOOKUP(C46,EconomicVariables!A:B,2,FALSE) -> Interest Rate | E46: decrease | F46: =F38 -> Contractionary fiscal policy使public savings=tax-(government spending+transfers)增加，增加Supply of Loans（或减少deficit spending进而减少Demand for Loans)，因而利率下降。见loanable funds market diagram
A47: 6 | B47: =VLOOKUP(A47,PolicyActions!A:B,2,FALSE) -> Decrease government spending | C47: 7 | D47: =VLOOKUP(C47,EconomicVariables!A:B,2,FALSE) -> Bond Price | E47: increase | F47: =F39 -> 债券价格与利率反向。（Contractionary fiscal policy使public savings=tax-(government spending+transfers)增加，增加Supply of Loans（或减少deficit spending进而减少Demand for Loans)，因而利率下降。见loanable funds market diagram）
A48: 6 | B48: =VLOOKUP(A48,PolicyActions!A:B,2,FALSE) -> Decrease government spending | C48: 8 | D48: =VLOOKUP(C48,EconomicVariables!A:B,2,FALSE) -> Interest-sensitive Private Spending (Investment & Consumption) | E48: increase | F48: =F40 -> Interest-sensitive Private Spending (Investment & Consumption)与利率反向。（Contractionary fiscal policy使public savings=tax-(government spending+transfers)增加，增加Supply of Loans（或减少deficit spending进而减少Demand for Loans)，因而利率下降。见loanable funds market diagram）
A49: 6 | B49: =VLOOKUP(A49,PolicyActions!A:B,2,FALSE) -> Decrease government spending | C49: 9 | D49: =VLOOKUP(C49,EconomicVariables!A:B,2,FALSE) -> Economic Growth (LRAS, PPC) | E49: increase | F49: =F41 -> Investment与利率反向，长期会影响capital stock资本存量（属于资源数量）和潜在产能。（Contractionary fiscal policy使public savings=tax-(government spending+transfers)增加，增加Supply of Loans（或减少deficit spending进而减少Demand for Loans)，因而利率下降。见loanable funds market diagram）
A50: 7 | B50: =VLOOKUP(A50,PolicyActions!A:B,2,FALSE) -> Decrease transfer payments | C50: 1 | D50: =VLOOKUP(C50,EconomicVariables!A:B,2,FALSE) -> Aggregate Demand | E50: decrease | F50: =F42 -> Contractionary fiscal policy减少AD，政府支出直接影响AD，税和转移支付影响disposable income，间接影响private spending和AD。
A51: 7 | B51: =VLOOKUP(A51,PolicyActions!A:B,2,FALSE) -> Decrease transfer payments | C51: 2 | D51: =VLOOKUP(C51,EconomicVariables!A:B,2,FALSE) -> Price Level | E51: decrease | F51: =F43 -> Contractionary fiscal policy减少AD，见AD-AS diagram
...

Sheet DiagramData
A1: id | B1: name | C1: curves
A2: 1 | B2: AD-AS Diagram | C2: Aggregate Demand,Short-run Aggregate Supply,Long-run Aggregate Supply
A3: 2 | B3: Money Market Diagram | C3: Money Supply,Money Demand
A4: 3 | B4: Loanable Funds Market | C4: Supply of Loanable Funds,Demand for Loanable Funds
A5: 4 | B5: Foreign Exchange Market | C5: Supply of Dollars,Demand for Dollars
A6: 5 | B6: Phillips Curve | C6: Short-run Phillips Curve,Long-run Phillips Curve

Sheet EconomicEvents
A1: id | B1: event | C1: affectedDiagram | D1: affectedCurve | E1: effect | F1: explanation | H1: 35 | I1: Expansionary fiscal policy (或increase government spending) | J1: Money Market Diagram | K1: Money Demand | L1: increase
A2: 1 | B2: Consumer confidence decreases | C2: AD-AS Diagram | D2: Aggregate Demand | E2: decrease
A3: 2 | B3: An increase in exports | C3: AD-AS Diagram | D3: Aggregate Demand | E3: increase
A4: 3 | B4: Increased spending by businesses on computers | C4: AD-AS Diagram | D4: Aggregate Demand | E4: increase
A5: 4 | B5: A decrease in household income | C5: AD-AS Diagram | D5: Aggregate Demand | E5: decrease
A6: 5 | B6: Consumers have large unpaid balances on their credit cards. | C6: AD-AS Diagram | D6: Aggregate Demand | E6: decrease
A7: 6 | B7: Consumers’ wealth is increased by changes in the stock market | C7: AD-AS Diagram | D7: Aggregate Demand | E7: increase
A8: 7 | B8: Population | C8: AD-AS Diagram | D8: Aggregate Demand | E8: increase
A9: 8 | B9: An increase in military spending | C9: AD-AS Diagram | D9: Aggregate Demand | E9: increase
A10: 9 | B10: A major trading partner experiences a recession | C10: AD-AS Diagram | D10: Aggregate Demand | E10: decrease
A11: 10 | B11: The optimism of business firms | C11: AD-AS Diagram | D11: Aggregate Demand | E11: increase
A12: 11 | B12: A increase in the expected rate of inflation | C12: AD-AS Diagram | D12: Aggregate Demand | E12: increase
A13: 12 | B13: Depreciation of this country's currency on the foreign exchange market | C13: AD-AS Diagram | D13: Aggregate Demand | E13: increase
... A51: 50 | B51: The economy is facing political instability. | C51: Loanable Funds Market | D51: Supply of Loanable Funds | E51: decrease
